<!DOCTYPE html>
<html lang="en">
<head></head>
<body>

<h3>Catch errors</h3>

<p>
    catch is useful for reacting to errors in a sequence, and it behaves much like the traditional try/catch block. In
    some cases, though, it would be very conve- nient to ignore an error that happens with an item in the Observable and
    let the sequence continue. In those cases, we can use the retry operator.
</p>

<script src="/lib/Rx5.umd.js"></script>
<script>
    function getJSON(arr) {
        return Rx.Observable.from(arr).map(function (str) {
            var parsedJSON = JSON.parse(str);
            return parsedJSON;
        });
    }


    // NOT USING CATCH()
    getJSON([
        '{"1": 1, "2": 2}',
        '{"success: true}', // Invalid JSON string
    ]).subscribe(function (json) {
                console.log('Parsed JSON: ', json);
            },
            function (err) {
                // this gets called as we didn't use catch() (below)
                console.log(11, err.message);
            });


    // USING CATCH()
    var caught = getJSON(['{"1": 1, "2": 2}', '{"1: 1}', '{"1": 1, "2": 2}'])
            .catch(Rx.Observable.return({
                error: 'There was an error parsing JSON'
            })
    );
    caught.subscribe(function (json) {
                console.log('Parsed JSON: ', json);
            },
            // Because we catch errors now, `onError` will not be executed
            function (e) {
                console.log('ERROR', e.message);
            });




</script>

</body>
</html>